<?xml version="1.0" ?>
<robot name="jaime_neck" xmlns:xacro="http://www.ros.org/wiki/xacro">

<xacro:include filename="$(find jaime_neck_description)/urdf/materials.xacro" />
<xacro:include filename="$(find jaime_neck_description)/urdf/jaime_neck.trans" />
<xacro:include filename="$(find jaime_neck_description)/urdf/jaime_neck.gazebo" />
<link name="base_link">
  <inertial>
    <origin xyz="-0.0015071371607443052 -0.045178581236278964 0.1966099517276674" rpy="0 0 0"/>
    <mass value="49.1345111063547"/>
    <inertia ixx="1.874356" iyy="2.194951" izz="0.476531" ixy="0.0" iyz="-0.0" ixz="0.472297"/>
  </inertial>
  <visual>
    <origin xyz="0 0 0" rpy="0 0 0"/>
    <geometry>
      <mesh filename="package://jaime_neck_description/meshes/base_link.stl" scale="0.001 0.001 0.001"/>
    </geometry>
    <material name="silver"/>
  </visual>
  <collision>
    <origin xyz="0 0 0" rpy="0 0 0"/>
    <geometry>
      <mesh filename="package://jaime_neck_description/meshes/base_link.stl" scale="0.001 0.001 0.001"/>
    </geometry>
  </collision>
</link>

<link name="l1_1">
  <inertial>
    <origin xyz="-0.02269974234167807 -0.014999581236279005 0.0445499817871311" rpy="0 0 0"/>
    <mass value="1.237938027968155"/>
    <inertia ixx="0.001558" iyy="0.001961" izz="0.000588" ixy="0.0" iyz="-0.0" ixz="0.000668"/>
  </inertial>
  <visual>
    <origin xyz="0.194767 0.030179 -0.781292" rpy="0 0 0"/>
    <geometry>
      <mesh filename="package://jaime_neck_description/meshes/l1_1.stl" scale="0.001 0.001 0.001"/>
    </geometry>
    <material name="silver"/>
  </visual>
  <collision>
    <origin xyz="0.194767 0.030179 -0.781292" rpy="0 0 0"/>
    <geometry>
      <mesh filename="package://jaime_neck_description/meshes/l1_1.stl" scale="0.001 0.001 0.001"/>
    </geometry>
  </collision>
</link>

<link name="l2_1">
  <inertial>
    <origin xyz="-0.04766928370441903 -0.014999581236279012 0.09355598476474769" rpy="0 0 0"/>
    <mass value="1.5249840239746273"/>
    <inertia ixx="0.003613" iyy="0.004325" izz="0.001294" ixy="0.0" iyz="-0.0" ixz="0.001596"/>
  </inertial>
  <visual>
    <origin xyz="0.240166 0.030179 -0.870392" rpy="0 0 0"/>
    <geometry>
      <mesh filename="package://jaime_neck_description/meshes/l2_1.stl" scale="0.001 0.001 0.001"/>
    </geometry>
    <material name="silver"/>
  </visual>
  <collision>
    <origin xyz="0.240166 0.030179 -0.870392" rpy="0 0 0"/>
    <geometry>
      <mesh filename="package://jaime_neck_description/meshes/l2_1.stl" scale="0.001 0.001 0.001"/>
    </geometry>
  </collision>
</link>

<link name="l3_1">
  <inertial>
    <origin xyz="-0.024969768568086748 -0.014999581236279102 0.04900502573654353" rpy="0 0 0"/>
    <mass value="1.3321380279681612"/>
    <inertia ixx="0.001918" iyy="0.002414" izz="0.000696" ixy="0.0" iyz="-0.0" ixz="0.000841"/>
  </inertial>
  <visual>
    <origin xyz="0.335504 0.030179 -1.057504" rpy="0 0 0"/>
    <geometry>
      <mesh filename="package://jaime_neck_description/meshes/l3_1.stl" scale="0.001 0.001 0.001"/>
    </geometry>
    <material name="silver"/>
  </visual>
  <collision>
    <origin xyz="0.335504 0.030179 -1.057504" rpy="0 0 0"/>
    <geometry>
      <mesh filename="package://jaime_neck_description/meshes/l3_1.stl" scale="0.001 0.001 0.001"/>
    </geometry>
  </collision>
</link>

<link name="l4_1">
  <inertial>
    <origin xyz="-0.0419943547369534 -0.014999581236279088 0.08241849444516047" rpy="0 0 0"/>
    <mass value="1.2109840372908334"/>
    <inertia ixx="0.002516" iyy="0.002965" izz="0.000948" ixy="0.0" iyz="-0.0" ixz="0.001079"/>
  </inertial>
  <visual>
    <origin xyz="0.385443 0.030179 -1.155514" rpy="0 0 0"/>
    <geometry>
      <mesh filename="package://jaime_neck_description/meshes/l4_1.stl" scale="0.001 0.001 0.001"/>
    </geometry>
    <material name="silver"/>
  </visual>
  <collision>
    <origin xyz="0.385443 0.030179 -1.155514" rpy="0 0 0"/>
    <geometry>
      <mesh filename="package://jaime_neck_description/meshes/l4_1.stl" scale="0.001 0.001 0.001"/>
    </geometry>
  </collision>
</link>

<link name="l5_1">
  <inertial>
    <origin xyz="-0.016114391661114558 -0.01499958123627861 0.03162496588110897" rpy="0 0 0"/>
    <mass value="0.9654457744721715"/>
    <inertia ixx="0.000778" iyy="0.000983" izz="0.000346" ixy="0.0" iyz="-0.0" ixz="0.000298"/>
  </inertial>
  <visual>
    <origin xyz="0.469431 0.030179 -1.320351" rpy="0 0 0"/>
    <geometry>
      <mesh filename="package://jaime_neck_description/meshes/l5_1.stl" scale="0.001 0.001 0.001"/>
    </geometry>
    <material name="silver"/>
  </visual>
  <collision>
    <origin xyz="0.469431 0.030179 -1.320351" rpy="0 0 0"/>
    <geometry>
      <mesh filename="package://jaime_neck_description/meshes/l5_1.stl" scale="0.001 0.001 0.001"/>
    </geometry>
  </collision>
</link>

<link name="l6_1">
  <inertial>
    <origin xyz="-0.012920274632011619 4.1876372177535037e-07 0.06941179014315724" rpy="0 0 0"/>
    <mass value="3.703390903699381"/>
    <inertia ixx="0.013166" iyy="0.01768" izz="0.023034" ixy="0.0" iyz="-0.0" ixz="-0.006791"/>
  </inertial>
  <visual>
    <origin xyz="0.521301 0.045179 -1.378096" rpy="0 0 0"/>
    <geometry>
      <mesh filename="package://jaime_neck_description/meshes/l6_1.stl" scale="0.001 0.001 0.001"/>
    </geometry>
    <material name="silver"/>
  </visual>
  <collision>
    <origin xyz="0.521301 0.045179 -1.378096" rpy="0 0 0"/>
    <geometry>
      <mesh filename="package://jaime_neck_description/meshes/l6_1.stl" scale="0.001 0.001 0.001"/>
    </geometry>
  </collision>
</link>

<joint name="l1_to_base_link" type="revolute">
  <origin xyz="-0.194767 -0.030179 0.781292" rpy="0 0 0"/>
  <parent link="base_link"/>
  <child link="l1_1"/>
  <axis xyz="0.0 1.0 -0.0"/>
  <limit upper="0.872665" lower="0.0" effort="100" velocity="100"/>
</joint>

<joint name="l2_to_l1" type="revolute">
  <origin xyz="-0.045399 0.0 0.0891" rpy="0 0 0"/>
  <parent link="l1_1"/>
  <child link="l2_1"/>
  <axis xyz="0.0 1.0 -0.0"/>
  <limit upper="0.872665" lower="0.0" effort="100" velocity="100"/>
</joint>

<joint name="l3_to_l2" type="revolute">
  <origin xyz="-0.095338 0.0 0.187112" rpy="0 0 0"/>
  <parent link="l2_1"/>
  <child link="l3_1"/>
  <axis xyz="-0.0 1.0 -0.0"/>
  <limit upper="0.872665" lower="0.0" effort="100" velocity="100"/>
</joint>

<joint name="l4_to_l3" type="revolute">
  <origin xyz="-0.049939 0.0 0.09801" rpy="0 0 0"/>
  <parent link="l3_1"/>
  <child link="l4_1"/>
  <axis xyz="0.0 1.0 -0.0"/>
  <limit upper="0.872665" lower="0.0" effort="100" velocity="100"/>
</joint>

<joint name="l5_to_l4" type="revolute">
  <origin xyz="-0.083988 0.0 0.164837" rpy="0 0 0"/>
  <parent link="l4_1"/>
  <child link="l5_1"/>
  <axis xyz="-0.0 1.0 -0.0"/>
  <limit upper="1.570796" lower="-1.570796" effort="100" velocity="100"/>
</joint>

<joint name="l6_to_l5" type="revolute">
  <origin xyz="-0.05187 -0.015 0.057745" rpy="0 0 0"/>
  <parent link="l5_1"/>
  <child link="l6_1"/>
  <axis xyz="-0.891007 -0.0 -0.45399"/>
  <limit upper="1.570796" lower="-1.570796" effort="100" velocity="100"/>
</joint>

</robot>
